Workbook

Sheet After removing missing values
A1: Country_id | B1: Country | C1: year | D1: GDP | E1: Export of Goods and Service | F1: FDInetinflows | G1: FDInetinflows | H1: Population | I1: Inf.CPI | J1: Tax.rev.%GDP | K1: Unemp.rate
A2: 1 | B2: Algeria | C2: 1970 | D2: 4.8634875e+09 | E2: 1073504640 | F2: 80120000 | G2: 80120000 | H2: 13795915 | I2: 6.6
A3: =IF(B3=B2, A2, A2+1) -> 1 | B3: Algeria | C3: 1971 | D3: 5.0772224e+09 | E3: 936367680 | F3: 600000 | G3: 600000 | H3: 14110271 | I3: 2.62664
A4: =IF(B4=B3, A3, A3+1) -> 1 | B4: Algeria | C4: 1972 | D4: 6.7667666e+09 | E4: 1383774080 | F4: 41490000 | G4: 41490000 | H4: 14439748 | I4: 3.65631
A5: =IF(B5=B4, A4, A4+1) -> 1 | B5: Algeria | C5: 1973 | D5: 8.7078479e+09 | E5: 2220820224 | F5: 51000000 | G5: 51000000 | H5: 14786469 | I5: 6.17284
A6: =IF(B6=B5, A5, A5+1) -> 1 | B6: Algeria | C6: 1974 | D6: 1.321003e+10 | E6: 5118759936 | F6: 358000000 | G6: 358000000 | H6: 15153602 | I6: 4.69961
A7: =IF(B7=B6, A6, A6+1) -> 1 | B7: Algeria | C7: 1975 | D7: 1.5557934e+10 | E7: 5241302528 | F7: 119000000 | G7: 119000000 | H7: 15724692 | I7: 8.23032
A8: =IF(B8=B7, A7, A7+1) -> 1 | B8: Algeria | C8: 1976 | D8: 1.7728347e+10 | E8: 5860031488 | F8: 187000000 | G8: 187000000 | H8: 16500516 | I8: 9.43074
A9: =IF(B9=B8, A8, A8+1) -> 1 | B9: Algeria | C9: 1977 | D9: 2.0971901e+10 | E9: 6414584832 | F9: 178452647 | G9: 178452647 | H9: 17134192 | I9: 11.9893
A10: =IF(B10=B9, A9, A9+1) -> 1 | B10: Algeria | C10: 1978 | D10: 2.6364491e+10 | E10: 6732393472 | F10: 135152172 | G10: 135152172 | H10: 17632645 | I10: 17.5239
A11: =IF(B11=B10, A10, A10+1) -> 1 | B11: Algeria | C11: 1979 | D11: 3.3243422e+10 | E11: 10354760932 | F11: 25692486 | G11: 25692486 | H11: 18166981 | I11: 11.3486
A12: =IF(B12=B11, A11, A11+1) -> 1 | B12: Algeria | C12: 1980 | D12: 4.2346381e+10 | E12: 14541095664 | F12: 348669038 | G12: 348669038 | H12: 18739378 | I12: 9.51782
A13: =IF(B13=B12, A12, A12+1) -> 1 | B13: Algeria | C13: 1981 | D13: 4.4348673e+10 | E13: 15338986631 | F13: 13207259 | G13: 13207259 | H13: 19351357 | I13: 14.6548
A14: =IF(B14=B13, A13, A13+1) -> 1 | B14: Algeria | C14: 1982 | D14: 4.5207089e+10 | E14: 13980227233 | F14: -53569193 | G14: -53569193 | H14: 20000096 | I14: 6.54251
... A20: =IF(B20=B19, A19, A19+1) -> 1 | B20: Algeria | C20: 1988 | D20: 5.9089067e+10 | E20: 9163454464 | F20: 13018265 | G20: 13018265 | H20: 24243018 | I20: 5.91154
A21: =IF(B21=B20, A20, A20+1) -> 1 | B21: Algeria | C21: 1989 | D21: 5.5634414e+10 | E21: 10369845248 | F21: 12091647 | G21: 12091647 | H21: 24889507 | I21: 9.30436 | K21: 17.64
A22: =IF(B22=B21, A21, A21+1) -> 1 | B22: Algeria | C22: 1990 | D22: 6.2048563e+10 | E22: 14546469696 | F22: 334915 | G22: 334915 | H22: 25518074 | I22: 16.6525 | K22: 21.26
A23: =IF(B23=B22, A22, A22+1) -> 1 | B23: Algeria | C23: 1991 | D23: 4.5715615e+10 | E23: 13311391352 | F23: 11638686 | G23: 11638686 | H23: 26133905 | I23: 25.8864 | K23: 20.6
A24: =IF(B24=B23, A23, A23+1) -> 1 | B24: Algeria | C24: 1992 | D24: 4.8003078e+10 | E24: 12154184704 | F24: 30000000 | G24: 30000000 | H24: 26748303 | I24: 31.6697 | K24: 24.38
A25: =IF(B25=B24, A24, A24+1) -> 1 | B25: Algeria | C25: 1993 | D25: 4.9945599e+10 | E25: 10880088064 | F25: 1000 | G25: 1000 | H25: 27354327 | I25: 20.5403 | K25: 26.23
A26: =IF(B26=B25, A25, A25+1) -> 1 | B26: Algeria | C26: 1994 | D26: 4.2543178e+10 | E26: 9585286555 | F26: 1000 | G26: 1000 | H26: 27937006 | I26: 29.0477 | K26: 27.74
A27: =IF(B27=B26, A26, A26+1) -> 1 | B27: Algeria | C27: 1995 | D27: 4.1764315e+10 | E27: 10940068840 | F27: 1000 | G27: 1000 | H27: 28478022 | I27: 29.7796 | K27: 31.84
A28: =IF(B28=B27, A27, A27+1) -> 1 | B28: Algeria | C28: 1996 | D28: 4.6941583e+10 | E28: 13970025409 | F28: 270000000 | G28: 270000000 | H28: 28984634 | I28: 18.6791
A29: =IF(B29=B28, A28, A28+1) -> 1 | B29: Algeria | C29: 1997 | D29: 4.8177612e+10 | E29: 14889922793 | F29: 260000000 | G29: 260000000 | H29: 29476031 | I29: 5.73352 | K29: 25.43
A30: =IF(B30=B29, A29, A29+1) -> 1 | B30: Algeria | C30: 1998 | D30: 4.8187748e+10 | E30: 10880000226 | F30: 606600000 | G30: 606600000 | H30: 29924668 | I30: 4.95016
A31: =IF(B31=B30, A30, A30+1) -> 1 | B31: Algeria | C31: 1999 | D31: 4.8640653e+10 | E31: 13692398973 | F31: 291600000 | G31: 291600000 | H31: 30346083 | I31: 2.64551
A32: =IF(B32=B31, A31, A31+1) -> 1 | B32: Algeria | C32: 2000 | D32: 5.4790393e+10 | E32: 23050163567 | F32: 280100000 | G32: 280100000 | H32: 30774621 | I32: 0.339163 | K32: 29.77
A33: =IF(B33=B32, A32, A32+1) -> 1 | B33: Algeria | C33: 2001 | D33: 5.4744713e+10 | E33: 20085454899 | F33: 1113105536 | G33: 1113105536 | H33: 31200985 | I33: 4.22599 | K33: 27.3
A34: =IF(B34=B33, A33, A33+1) -> 1 | B34: Algeria | C34: 2002 | D34: 5.6760356e+10 | E34: 20152501384 | F34: 1064960000 | G34: 1064960000 | H34: 31624696 | I34: 1.4183 | K34: 25.9
A35: =IF(B35=B34, A34, A34+1) -> 1 | B35: Algeria | C35: 2003 | D35: 6.7863828e+10 | E35: 25957119969 | F35: 637853056 | G35: 637853056 | H35: 32055883 | I35: 4.26895 | K35: 23.72
A36: =IF(B36=B35, A35, A35+1) -> 1 | B36: Algeria | C36: 2004 | D36: 8.5332581e+10 | E36: 34178449805 | F36: 884749028 | G36: 884749028 | H36: 32510186 | I36: 3.9618 | K36: 17.65
A37: =IF(B37=B36, A36, A36+1) -> 1 | B37: Algeria | C37: 2005 | D37: 1.0319822e+11 | E37: 48714922833 | F37: 1156000000 | G37: 1156000000 | H37: 32956690 | I37: 1.38245 | K37: 15.27
A38: =IF(B38=B37, A37, A37+1) -> 1 | B38: Algeria | C38: 2006 | D38: 1.1702731e+11 | E38: 57121832267 | F38: 1840999936 | G38: 1840999936 | H38: 33435080 | I38: 2.3115 | K38: 12.27
A39: =IF(B39=B38, A38, A38+1) -> 1 | B39: Algeria | C39: 2007 | D39: 1.3497708e+11 | E39: 63531235749 | F39: 1686736512 | G39: 1686736512 | H39: 33983827 | I39: 3.679 | K39: 13.79
A40: =IF(B40=B39, A39, A39+1) -> 1 | B40: Algeria | C40: 2008 | D40: 1.710007e+11 | E40: 82034752287 | F40: 2638607104 | G40: 2638607104 | H40: 34569592 | I40: 4.85859 | K40: 11.33
A41: =IF(B41=B40, A40, A40+1) -> 1 | B41: Algeria | C41: 2009 | D41: 1.3721104e+11 | E41: 48533809882 | F41: 2746930688 | G41: 2746930688 | H41: 35196037 | I41: 5.73706 | K41: 10.16
A42: =IF(B42=B41, A41, A41+1) -> 1 | B42: Algeria | C42: 2010 | D42: 1.6120727e+11 | E42: 61975405318 | F42: 2300369152 | G42: 2300369152 | H42: 35856344 | I42: 3.91106 | K42: 9.96
A43: =IF(B43=B42, A42, A42+1) -> 1 | B43: Algeria | C43: 2011 | D43: 2.0001305e+11 | E43: 77581299983 | F43: 2571237120 | G43: 2571237120 | H43: 36543541 | I43: 4.52421 | K43: 9.96
... A49: =IF(B49=B48, A48, A48+1) -> 1 | B49: Algeria | C49: 2017 | D49: 1.7009701e+11 | E49: 38496751462 | F49: 1230243456 | G49: 1230243456 | H49: 41136546 | I49: 5.59112 | K49: 12
A50: =IF(B50=B49, A49, A49+1) -> 1 | B50: Algeria | C50: 2018 | D50: 1.7491088e+11 | E50: 45233966129 | F50: 1466116096 | G50: 1466116096 | H50: 41927007 | I50: 4.26999
...

Sheet After FDI>0
A1: Country_id | B1: Country | C1: year | D1: GDP | E1: Export of Goods and Service | F1: FDInetinflows | G1: Population | H1: Inf.CPI | I1: Tax.rev.%GDP | J1: Unemp.rate
A2: 1 | B2: Algeria | C2: 1970 | D2: 4.8634875e+09 | E2: 1073504640 | F2: 80120000 | G2: 13795915 | H2: 6.6
A3: =IF(B3=B2, A2, A2+1) -> 1 | B3: Algeria | C3: 1971 | D3: 5.0772224e+09 | E3: 936367680 | F3: 600000 | G3: 14110271 | H3: 2.62664
A4: =IF(B4=B3, A3, A3+1) -> 1 | B4: Algeria | C4: 1972 | D4: 6.7667666e+09 | E4: 1383774080 | F4: 41490000 | G4: 14439748 | H4: 3.65631
A5: =IF(B5=B4, A4, A4+1) -> 1 | B5: Algeria | C5: 1973 | D5: 8.7078479e+09 | E5: 2220820224 | F5: 51000000 | G5: 14786469 | H5: 6.17284
A6: =IF(B6=B5, A5, A5+1) -> 1 | B6: Algeria | C6: 1974 | D6: 1.321003e+10 | E6: 5118759936 | F6: 358000000 | G6: 15153602 | H6: 4.69961
A7: =IF(B7=B6, A6, A6+1) -> 1 | B7: Algeria | C7: 1975 | D7: 1.5557934e+10 | E7: 5241302528 | F7: 119000000 | G7: 15724692 | H7: 8.23032
A8: =IF(B8=B7, A7, A7+1) -> 1 | B8: Algeria | C8: 1976 | D8: 1.7728347e+10 | E8: 5860031488 | F8: 187000000 | G8: 16500516 | H8: 9.43074
A9: =IF(B9=B8, A8, A8+1) -> 1 | B9: Algeria | C9: 1977 | D9: 2.0971901e+10 | E9: 6414584832 | F9: 178452647 | G9: 17134192 | H9: 11.9893
A10: =IF(B10=B9, A9, A9+1) -> 1 | B10: Algeria | C10: 1978 | D10: 2.6364491e+10 | E10: 6732393472 | F10: 135152172 | G10: 17632645 | H10: 17.5239
A11: =IF(B11=B10, A10, A10+1) -> 1 | B11: Algeria | C11: 1979 | D11: 3.3243422e+10 | E11: 10354760932 | F11: 25692486 | G11: 18166981 | H11: 11.3486
A12: =IF(B12=B11, A11, A11+1) -> 1 | B12: Algeria | C12: 1980 | D12: 4.2346381e+10 | E12: 14541095664 | F12: 348669038 | G12: 18739378 | H12: 9.51782
A13: =IF(B13=B12, A12, A12+1) -> 1 | B13: Algeria | C13: 1981 | D13: 4.4348673e+10 | E13: 15338986631 | F13: 13207259 | G13: 19351357 | H13: 14.6548
A14: =IF(B14=B13, A13, A13+1) -> 1 | B14: Algeria | C14: 1982 | D14: 4.5207089e+10 | E14: 13980227233 | F14: -53569193 | G14: 20000096 | H14: 6.54251
... A20: =IF(B20=B19, A19, A19+1) -> 1 | B20: Algeria | C20: 1988 | D20: 5.9089067e+10 | E20: 9163454464 | F20: 13018265 | G20: 24243018 | H20: 5.91154
A21: =IF(B21=B20, A20, A20+1) -> 1 | B21: Algeria | C21: 1989 | D21: 5.5634414e+10 | E21: 10369845248 | F21: 12091647 | G21: 24889507 | H21: 9.30436 | J21: 17.64
A22: =IF(B22=B21, A21, A21+1) -> 1 | B22: Algeria | C22: 1990 | D22: 6.2048563e+10 | E22: 14546469696 | F22: 334915 | G22: 25518074 | H22: 16.6525 | J22: 21.26
A23: =IF(B23=B22, A22, A22+1) -> 1 | B23: Algeria | C23: 1991 | D23: 4.5715615e+10 | E23: 13311391352 | F23: 11638686 | G23: 26133905 | H23: 25.8864 | J23: 20.6
A24: =IF(B24=B23, A23, A23+1) -> 1 | B24: Algeria | C24: 1992 | D24: 4.8003078e+10 | E24: 12154184704 | F24: 30000000 | G24: 26748303 | H24: 31.6697 | J24: 24.38
A25: =IF(B25=B24, A24, A24+1) -> 1 | B25: Algeria | C25: 1993 | D25: 4.9945599e+10 | E25: 10880088064 | F25: 1000 | G25: 27354327 | H25: 20.5403 | J25: 26.23
A26: =IF(B26=B25, A25, A25+1) -> 1 | B26: Algeria | C26: 1994 | D26: 4.2543178e+10 | E26: 9585286555 | F26: 1000 | G26: 27937006 | H26: 29.0477 | J26: 27.74
A27: =IF(B27=B26, A26, A26+1) -> 1 | B27: Algeria | C27: 1995 | D27: 4.1764315e+10 | E27: 10940068840 | F27: 1000 | G27: 28478022 | H27: 29.7796 | J27: 31.84
A28: =IF(B28=B27, A27, A27+1) -> 1 | B28: Algeria | C28: 1996 | D28: 4.6941583e+10 | E28: 13970025409 | F28: 270000000 | G28: 28984634 | H28: 18.6791
A29: =IF(B29=B28, A28, A28+1) -> 1 | B29: Algeria | C29: 1997 | D29: 4.8177612e+10 | E29: 14889922793 | F29: 260000000 | G29: 29476031 | H29: 5.73352 | J29: 25.43
A30: =IF(B30=B29, A29, A29+1) -> 1 | B30: Algeria | C30: 1998 | D30: 4.8187748e+10 | E30: 10880000226 | F30: 606600000 | G30: 29924668 | H30: 4.95016
A31: =IF(B31=B30, A30, A30+1) -> 1 | B31: Algeria | C31: 1999 | D31: 4.8640653e+10 | E31: 13692398973 | F31: 291600000 | G31: 30346083 | H31: 2.64551
A32: =IF(B32=B31, A31, A31+1) -> 1 | B32: Algeria | C32: 2000 | D32: 5.4790393e+10 | E32: 23050163567 | F32: 280100000 | G32: 30774621 | H32: 0.339163 | J32: 29.77
A33: =IF(B33=B32, A32, A32+1) -> 1 | B33: Algeria | C33: 2001 | D33: 5.4744713e+10 | E33: 20085454899 | F33: 1113105536 | G33: 31200985 | H33: 4.22599 | J33: 27.3
A34: =IF(B34=B33, A33, A33+1) -> 1 | B34: Algeria | C34: 2002 | D34: 5.6760356e+10 | E34: 20152501384 | F34: 1064960000 | G34: 31624696 | H34: 1.4183 | J34: 25.9
A35: =IF(B35=B34, A34, A34+1) -> 1 | B35: Algeria | C35: 2003 | D35: 6.7863828e+10 | E35: 25957119969 | F35: 637853056 | G35: 32055883 | H35: 4.26895 | J35: 23.72
A36: =IF(B36=B35, A35, A35+1) -> 1 | B36: Algeria | C36: 2004 | D36: 8.5332581e+10 | E36: 34178449805 | F36: 884749028 | G36: 32510186 | H36: 3.9618 | J36: 17.65
A37: =IF(B37=B36, A36, A36+1) -> 1 | B37: Algeria | C37: 2005 | D37: 1.0319822e+11 | E37: 48714922833 | F37: 1156000000 | G37: 32956690 | H37: 1.38245 | J37: 15.27
A38: =IF(B38=B37, A37, A37+1) -> 1 | B38: Algeria | C38: 2006 | D38: 1.1702731e+11 | E38: 57121832267 | F38: 1840999936 | G38: 33435080 | H38: 2.3115 | J38: 12.27
A39: =IF(B39=B38, A38, A38+1) -> 1 | B39: Algeria | C39: 2007 | D39: 1.3497708e+11 | E39: 63531235749 | F39: 1686736512 | G39: 33983827 | H39: 3.679 | J39: 13.79
A40: =IF(B40=B39, A39, A39+1) -> 1 | B40: Algeria | C40: 2008 | D40: 1.710007e+11 | E40: 82034752287 | F40: 2638607104 | G40: 34569592 | H40: 4.85859 | J40: 11.33
A41: =IF(B41=B40, A40, A40+1) -> 1 | B41: Algeria | C41: 2009 | D41: 1.3721104e+11 | E41: 48533809882 | F41: 2746930688 | G41: 35196037 | H41: 5.73706 | J41: 10.16
A42: =IF(B42=B41, A41, A41+1) -> 1 | B42: Algeria | C42: 2010 | D42: 1.6120727e+11 | E42: 61975405318 | F42: 2300369152 | G42: 35856344 | H42: 3.91106 | J42: 9.96
A43: =IF(B43=B42, A42, A42+1) -> 1 | B43: Algeria | C43: 2011 | D43: 2.0001305e+11 | E43: 77581299983 | F43: 2571237120 | G43: 36543541 | H43: 4.52421 | J43: 9.96
... A49: =IF(B49=B48, A48, A48+1) -> 1 | B49: Algeria | C49: 2017 | D49: 1.7009701e+11 | E49: 38496751462 | F49: 1230243456 | G49: 41136546 | H49: 5.59112 | J49: 12
A50: =IF(B50=B49, A49, A49+1) -> 1 | B50: Algeria | C50: 2018 | D50: 1.7491088e+11 | E50: 45233966129 | F50: 1466116096 | G50: 41927007 | H50: 4.26999
...

Sheet FDI>0
A1: Country_id | B1: Country | C1: year | D1: GDP | E1: Export of Goods and Service | F1: FDInetinflows | G1: Population | H1: Inf.CPI | I1: Tax.rev.%GDP | J1: Unemp.rate
A2: 1 | B2: Algeria | C2: 1970 | D2: 4.8634875e+09 | E2: 1073504640 | F2: 80120000 | G2: 13795915 | H2: 6.6
A3: 1 | B3: Algeria | C3: 1971 | D3: 5.0772224e+09 | E3: 936367680 | F3: 600000 | G3: 14110271 | H3: 2.62664
A4: 1 | B4: Algeria | C4: 1972 | D4: 6.7667666e+09 | E4: 1383774080 | F4: 41490000 | G4: 14439748 | H4: 3.65631
A5: 1 | B5: Algeria | C5: 1973 | D5: 8.7078479e+09 | E5: 2220820224 | F5: 51000000 | G5: 14786469 | H5: 6.17284
A6: 1 | B6: Algeria | C6: 1974 | D6: 1.321003e+10 | E6: 5118759936 | F6: 358000000 | G6: 15153602 | H6: 4.69961
A7: 1 | B7: Algeria | C7: 1975 | D7: 1.5557934e+10 | E7: 5241302528 | F7: 119000000 | G7: 15724692 | H7: 8.23032
A8: 1 | B8: Algeria | C8: 1976 | D8: 1.7728347e+10 | E8: 5860031488 | F8: 187000000 | G8: 16500516 | H8: 9.43074
A9: 1 | B9: Algeria | C9: 1977 | D9: 2.0971901e+10 | E9: 6414584832 | F9: 178452647 | G9: 17134192 | H9: 11.9893
A10: 1 | B10: Algeria | C10: 1978 | D10: 2.6364491e+10 | E10: 6732393472 | F10: 135152172 | G10: 17632645 | H10: 17.5239
A11: 1 | B11: Algeria | C11: 1979 | D11: 3.3243422e+10 | E11: 10354760932 | F11: 25692486 | G11: 18166981 | H11: 11.3486
A12: 1 | B12: Algeria | C12: 1980 | D12: 4.2346381e+10 | E12: 14541095664 | F12: 348669038 | G12: 18739378 | H12: 9.51782
A13: 1 | B13: Algeria | C13: 1981 | D13: 4.4348673e+10 | E13: 15338986631 | F13: 13207259 | G13: 19351357 | H13: 14.6548
... A19: 1 | B19: Algeria | C19: 1988 | D19: 5.9089067e+10 | E19: 9163454464 | F19: 13018265 | G19: 24243018 | H19: 5.91154
A20: 1 | B20: Algeria | C20: 1989 | D20: 5.5634414e+10 | E20: 10369845248 | F20: 12091647 | G20: 24889507 | H20: 9.30436 | J20: 17.64
A21: 1 | B21: Algeria | C21: 1990 | D21: 6.2048563e+10 | E21: 14546469696 | F21: 334915 | G21: 25518074 | H21: 16.6525 | J21: 21.26
A22: 1 | B22: Algeria | C22: 1991 | D22: 4.5715615e+10 | E22: 13311391352 | F22: 11638686 | G22: 26133905 | H22: 25.8864 | J22: 20.6
A23: 1 | B23: Algeria | C23: 1992 | D23: 4.8003078e+10 | E23: 12154184704 | F23: 30000000 | G23: 26748303 | H23: 31.6697 | J23: 24.38
A24: 1 | B24: Algeria | C24: 1993 | D24: 4.9945599e+10 | E24: 10880088064 | F24: 1000 | G24: 27354327 | H24: 20.5403 | J24: 26.23
A25: 1 | B25: Algeria | C25: 1994 | D25: 4.2543178e+10 | E25: 9585286555 | F25: 1000 | G25: 27937006 | H25: 29.0477 | J25: 27.74
A26: 1 | B26: Algeria | C26: 1995 | D26: 4.1764315e+10 | E26: 10940068840 | F26: 1000 | G26: 28478022 | H26: 29.7796 | J26: 31.84
A27: 1 | B27: Algeria | C27: 1996 | D27: 4.6941583e+10 | E27: 13970025409 | F27: 270000000 | G27: 28984634 | H27: 18.6791
A28: 1 | B28: Algeria | C28: 1997 | D28: 4.8177612e+10 | E28: 14889922793 | F28: 260000000 | G28: 29476031 | H28: 5.73352 | J28: 25.43
A29: 1 | B29: Algeria | C29: 1998 | D29: 4.8187748e+10 | E29: 10880000226 | F29: 606600000 | G29: 29924668 | H29: 4.95016
A30: 1 | B30: Algeria | C30: 1999 | D30: 4.8640653e+10 | E30: 13692398973 | F30: 291600000 | G30: 30346083 | H30: 2.64551
A31: 1 | B31: Algeria | C31: 2000 | D31: 5.4790393e+10 | E31: 23050163567 | F31: 280100000 | G31: 30774621 | H31: 0.339163 | J31: 29.77
A32: 1 | B32: Algeria | C32: 2001 | D32: 5.4744713e+10 | E32: 20085454899 | F32: 1113105536 | G32: 31200985 | H32: 4.22599 | J32: 27.3
A33: 1 | B33: Algeria | C33: 2002 | D33: 5.6760356e+10 | E33: 20152501384 | F33: 1064960000 | G33: 31624696 | H33: 1.4183 | J33: 25.9
A34: 1 | B34: Algeria | C34: 2003 | D34: 6.7863828e+10 | E34: 25957119969 | F34: 637853056 | G34: 32055883 | H34: 4.26895 | J34: 23.72
A35: 1 | B35: Algeria | C35: 2004 | D35: 8.5332581e+10 | E35: 34178449805 | F35: 884749028 | G35: 32510186 | H35: 3.9618 | J35: 17.65
A36: 1 | B36: Algeria | C36: 2005 | D36: 1.0319822e+11 | E36: 48714922833 | F36: 1156000000 | G36: 32956690 | H36: 1.38245 | J36: 15.27
A37: 1 | B37: Algeria | C37: 2006 | D37: 1.1702731e+11 | E37: 57121832267 | F37: 1840999936 | G37: 33435080 | H37: 2.3115 | J37: 12.27
A38: 1 | B38: Algeria | C38: 2007 | D38: 1.3497708e+11 | E38: 63531235749 | F38: 1686736512 | G38: 33983827 | H38: 3.679 | J38: 13.79
A39: 1 | B39: Algeria | C39: 2008 | D39: 1.710007e+11 | E39: 82034752287 | F39: 2638607104 | G39: 34569592 | H39: 4.85859 | J39: 11.33
A40: 1 | B40: Algeria | C40: 2009 | D40: 1.3721104e+11 | E40: 48533809882 | F40: 2746930688 | G40: 35196037 | H40: 5.73706 | J40: 10.16
A41: 1 | B41: Algeria | C41: 2010 | D41: 1.6120727e+11 | E41: 61975405318 | F41: 2300369152 | G41: 35856344 | H41: 3.91106 | J41: 9.96
A42: 1 | B42: Algeria | C42: 2011 | D42: 2.0001305e+11 | E42: 77581299983 | F42: 2571237120 | G42: 36543541 | H42: 4.52421 | J42: 9.96
... A47: 1 | B47: Algeria | C47: 2017 | D47: 1.7009701e+11 | E47: 38496751462 | F47: 1230243456 | G47: 41136546 | H47: 5.59112 | J47: 12
A48: 1 | B48: Algeria | C48: 2018 | D48: 1.7491088e+11 | E48: 45233966129 | F48: 1466116096 | G48: 41927007 | H48: 4.26999
A49: 1 | B49: Algeria | C49: 2019 | D49: 1.717674e+11 | E49: 39014323824 | F49: 1381200000 | G49: 42705368 | H49: 1.95177
...

Sheet After Inf>0
A1: Country_id | B1: Country | C1: year | D1: GDP | E1: FDInetinflows | F1: Population | G1: Inf.CPI | H1: Trade
A2: 1 | B2: Algeria | C2: 1970 | D2: 4.8634875e+09 | E2: 80120000 | F2: 13795915 | G2: 6.6
A3: 1 | B3: Algeria | C3: 1971 | D3: 5.0772224e+09 | E3: 600000 | F3: 14110271 | G3: 2.62664
A4: 1 | B4: Algeria | C4: 1972 | D4: 6.7667666e+09 | E4: 41490000 | F4: 14439748 | G4: 3.65631
A5: 1 | B5: Algeria | C5: 1973 | D5: 8.7078479e+09 | E5: 51000000 | F5: 14786469 | G5: 6.17284
A6: 1 | B6: Algeria | C6: 1974 | D6: 1.321003e+10 | E6: 358000000 | F6: 15153602 | G6: 4.69961
A7: 1 | B7: Algeria | C7: 1975 | D7: 1.5557934e+10 | E7: 119000000 | F7: 15724692 | G7: 8.23032
A8: 1 | B8: Algeria | C8: 1976 | D8: 1.7728347e+10 | E8: 187000000 | F8: 16500516 | G8: 9.43074
A9: 1 | B9: Algeria | C9: 1977 | D9: 2.0971901e+10 | E9: 178452647 | F9: 17134192 | G9: 11.9893
A10: 1 | B10: Algeria | C10: 1978 | D10: 2.6364491e+10 | E10: 135152172 | F10: 17632645 | G10: 17.5239
A11: 1 | B11: Algeria | C11: 1979 | D11: 3.3243422e+10 | E11: 25692486 | F11: 18166981 | G11: 11.3486
A12: 1 | B12: Algeria | C12: 1980 | D12: 4.2346381e+10 | E12: 348669038 | F12: 18739378 | G12: 9.51782
A13: 1 | B13: Algeria | C13: 1981 | D13: 4.4348673e+10 | E13: 13207259 | F13: 19351357 | G13: 14.6548
... A3628: 91 | B3628: Zimbabwe | C3628: 2021 | D3628: 2.8371239e+10 | E3628: 166000000 | F3628: 15993524 | G3628: 98.5461

Sheet Sheet2
A1: Country_id | B1: Country | C1: year | D1: GDP | E1: Log_gdp | F1: FDInetinflows | G1: Log_FDI | H1: Population | I1: Log_Pop | J1: Inf.CPI | K1: Log_inf
A2: 1 | B2: Algeria | C2: 1970 | D2: 4.8634875e+09 | E2: =LN(D2) -> 22.305022 | F2: 80120000 | G2: =LN(F2) -> 18.199036 | H2: 13795915 | I2: =LN(H2) -> 16.439883 | J2: 6.6 | K2: =LN(J2) -> 1.8870696
A3: 1 | B3: Algeria | C3: 1971 | D3: 5.0772224e+09 | E3: =LN(D3) -> 22.34803 | F3: 600000 | G3: =LN(F3) -> 13.304685 | H3: 14110271 | I3: =LN(H3) -> 16.462414 | J3: 2.62664 | K3: =LN(J3) -> 0.96570546
A4: 1 | B4: Algeria | C4: 1972 | D4: 6.7667666e+09 | E4: =LN(D4) -> 22.635289 | F4: 41490000 | G4: =LN(F4) -> 17.540963 | H4: 14439748 | I4: =LN(H4) -> 16.485495 | J4: 3.65631 | K4: =LN(J4) -> 1.2964544
A5: 1 | B5: Algeria | C5: 1973 | D5: 8.7078479e+09 | E5: =LN(D5) -> 22.887491 | F5: 51000000 | G5: =LN(F5) -> 17.747336 | H5: 14786469 | I5: =LN(H5) -> 16.509223 | J5: 6.17284 | K5: =LN(J5) -> 1.820159
A6: 1 | B6: Algeria | C6: 1974 | D6: 1.321003e+10 | E6: =LN(D6) -> 23.304242 | F6: 358000000 | G6: =LN(F6) -> 19.696044 | H6: 15153602 | I6: =LN(H6) -> 16.533749 | J6: 4.69961 | K6: =LN(J6) -> 1.5474795
A7: 1 | B7: Algeria | C7: 1975 | D7: 1.5557934e+10 | E7: =LN(D7) -> 23.467837 | F7: 119000000 | G7: =LN(F7) -> 18.594634 | H7: 15724692 | I7: =LN(H7) -> 16.570743 | J7: 8.23032 | K7: =LN(J7) -> 2.1078249
A8: 1 | B8: Algeria | C8: 1976 | D8: 1.7728347e+10 | E8: =LN(D8) -> 23.598431 | F8: 187000000 | G8: =LN(F8) -> 19.046619 | H8: 16500516 | I8: =LN(H8) -> 16.618902 | J8: 9.43074 | K8: =LN(J8) -> 2.2439746
A9: 1 | B9: Algeria | C9: 1977 | D9: 2.0971901e+10 | E9: =LN(D9) -> 23.766449 | F9: 178452647 | G9: =LN(F9) -> 18.999834 | H9: 17134192 | I9: =LN(H9) -> 16.656587 | J9: 11.9893 | K9: =LN(J9) -> 2.4840146
A10: 1 | B10: Algeria | C10: 1978 | D10: 2.6364491e+10 | E10: =LN(D10) -> 23.995284 | F10: 135152172 | G10: =LN(F10) -> 18.721912 | H10: 17632645 | I10: =LN(H10) -> 16.685263 | J10: 17.5239 | K10: =LN(J10) -> 2.8635657
A11: 1 | B11: Algeria | C11: 1979 | D11: 3.3243422e+10 | E11: =LN(D11) -> 24.227123 | F11: 25692486 | G11: =LN(F11) -> 17.061709 | H11: 18166981 | I11: =LN(H11) -> 16.715116 | J11: 11.3486 | K11: =LN(J11) -> 2.4290944
A12: 1 | B12: Algeria | C12: 1980 | D12: 4.2346381e+10 | E12: =LN(D12) -> 24.469149 | F12: 348669038 | G12: =LN(F12) -> 19.669634 | H12: 18739378 | I12: =LN(H12) -> 16.746138 | J12: 9.51782 | K12: =LN(J12) -> 2.2531658
A13: 1 | B13: Algeria | C13: 1981 | D13: 4.4348673e+10 | E13: =LN(D13) -> 24.515349 | F13: 13207259 | G13: =LN(F13) -> 16.396277 | H13: 19351357 | I13: =LN(H13) -> 16.778273 | J13: 14.6548 | K13: =LN(J13) -> 2.6847679
... A3628: 91 | B3628: Zimbabwe | C3628: 2021 | D3628: 2.8371239e+10 | E3628: =LN(D3628) -> 24.068642 | F3628: 166000000 | G3628: =LN(F3628) -> 18.927498 | H3628: 15993524 | I3628: =LN(H3628) -> 16.587694 | J3628: 98.5461 | K3628: =LN(J3628) -> 4.5905245

Sheet Final_data
A1: Country_id | B1: Country | C1: year | D1: Log_gdp | E1: Log_FDI | F1: Log_Pop | G1: Log_inf
A2: 1 | B2: Algeria | C2: 1970 | D2: 22.305022 | E2: 18.199036 | F2: 16.439883 | G2: 1.8870696
A3: 1 | B3: Algeria | C3: 1971 | D3: 22.34803 | E3: 13.304685 | F3: 16.462414 | G3: 0.96570546
A4: 1 | B4: Algeria | C4: 1972 | D4: 22.635289 | E4: 17.540963 | F4: 16.485495 | G4: 1.2964544
A5: 1 | B5: Algeria | C5: 1973 | D5: 22.887491 | E5: 17.747336 | F5: 16.509223 | G5: 1.820159
A6: 1 | B6: Algeria | C6: 1974 | D6: 23.304242 | E6: 19.696044 | F6: 16.533749 | G6: 1.5474795
A7: 1 | B7: Algeria | C7: 1975 | D7: 23.467837 | E7: 18.594634 | F7: 16.570743 | G7: 2.1078249
A8: 1 | B8: Algeria | C8: 1976 | D8: 23.598431 | E8: 19.046619 | F8: 16.618902 | G8: 2.2439746
A9: 1 | B9: Algeria | C9: 1977 | D9: 23.766449 | E9: 18.999834 | F9: 16.656587 | G9: 2.4840146
A10: 1 | B10: Algeria | C10: 1978 | D10: 23.995284 | E10: 18.721912 | F10: 16.685263 | G10: 2.8635657
A11: 1 | B11: Algeria | C11: 1979 | D11: 24.227123 | E11: 17.061709 | F11: 16.715116 | G11: 2.4290944
A12: 1 | B12: Algeria | C12: 1980 | D12: 24.469149 | E12: 19.669634 | F12: 16.746138 | G12: 2.2531658
A13: 1 | B13: Algeria | C13: 1981 | D13: 24.515349 | E13: 16.396277 | F13: 16.778273 | G13: 2.6847679
... A3628: 88 | B3628: Zimbabwe | C3628: 2021 | D3628: 24.068642 | E3628: 18.927498 | F3628: 16.587694 | G3628: 4.5905245

Sheet Sheet1
A1: Trade Openness
A2: 51.2254 | B2: =VLOOKUP(Final_data!C2:C51, [2]Sheet2!$B$136:$B$187, 1,) -> 1970
A3: 46.1063 | B3: =VLOOKUP(Final_data!C3:C52, [2]Sheet2!$B$136:$B$187, 1,) -> 1971
A4: 46.1764 | B4: =VLOOKUP(Final_data!C4:C53, [2]Sheet2!$B$136:$B$187, 1,) -> 1972
A5: 57.0934 | B5: =VLOOKUP(Final_data!C5:C54, [2]Sheet2!$B$136:$B$187, 1,) -> 1973
A6: 74.2388 | B6: =VLOOKUP(Final_data!C6:C55, [2]Sheet2!$B$136:$B$187, 1,) -> 1974
A7: 76.6545 | B7: =VLOOKUP(Final_data!C7:C56, [2]Sheet2!$B$136:$B$187, 1,) -> 1975
A8: 70.1733 | B8: =VLOOKUP(Final_data!C8:C57, [2]Sheet2!$B$136:$B$187, 1,) -> 1976
A9: 72.3269 | B9: =VLOOKUP(Final_data!C9:C58, [2]Sheet2!$B$136:$B$187, 1,) -> 1977
A10: 65.7046 | B10: =VLOOKUP(Final_data!C10:C59, [2]Sheet2!$B$136:$B$187, 1,) -> 1978
A11: 64.014 | B11: =VLOOKUP(Final_data!C11:C60, [2]Sheet2!$B$136:$B$187, 1,) -> 1979
A12: 64.6769 | B12: =VLOOKUP(Final_data!C12:C61, [2]Sheet2!$B$136:$B$187, 1,) -> 1980
A13: 65.465 | B13: =VLOOKUP(Final_data!C13:C62, [2]Sheet2!$B$136:$B$187, 1,) -> 1981
... A51: 52.9701 | B51: =VLOOKUP(Final_data!C51:C100, [2]Sheet2!$B$136:$B$187, 1,) -> 2021
A52: 26.1536
A53: 25.5548
A54: 24.7576
A55: 25.132
A56: 26.3229
A57: 28.9702
A58: 26.8629
A59: 28.6308
A60: 28.1778
A61: 29.6242
A62: 32.299
A63: 31.6041
... A112: 63.3172
A113: 66.825 | B113: =VLOOKUP(Final_data!C113:C162, [2]Sheet2!$B$136:$B$187, 1,) -> 1980
A114: 68.3966 | B114: =VLOOKUP(Final_data!C114:C163, [2]Sheet2!$B$136:$B$187, 1,) -> 1981
A115: 64.1171 | B115: =VLOOKUP(Final_data!C115:C164, [2]Sheet2!$B$136:$B$187, 1,) -> 1982
A116: 62.4722 | B116: =VLOOKUP(Final_data!C116:C165, [2]Sheet2!$B$136:$B$187, 1,) -> 1983
A117: 66.575 | B117: =VLOOKUP(Final_data!C117:C166, [2]Sheet2!$B$136:$B$187, 1,) -> 1984
A118: 70.0832 | B118: =VLOOKUP(Final_data!C118:C167, [2]Sheet2!$B$136:$B$187, 1,) -> 1985
A119: 64.0146 | B119: =VLOOKUP(Final_data!C119:C168, [2]Sheet2!$B$136:$B$187, 1,) -> 1986
A120: 62.8537 | B120: =VLOOKUP(Final_data!C120:C169, [2]Sheet2!$B$136:$B$187, 1,) -> 1987
A121: 66.5625 | B121: =VLOOKUP(Final_data!C121:C170, [2]Sheet2!$B$136:$B$187, 1,) -> 1988
A122: 70.5384 | B122: =VLOOKUP(Final_data!C122:C171, [2]Sheet2!$B$136:$B$187, 1,) -> 1989
A123: 71.4884 | B123: =VLOOKUP(Final_data!C123:C172, [2]Sheet2!$B$136:$B$187, 1,) -> 1990
A124: 70.0484 | B124: =VLOOKUP(Final_data!C124:C173, [2]Sheet2!$B$136:$B$187, 1,) -> 1991
... A373: 94.4795 | B373: =VLOOKUP(Final_data!C373:C422, [2]Sheet2!$B$136:$B$187, 1,) -> 2021
...

Sheet Sheet3
